Traceback (most recent call last):
  File "C:\Users\karen\anaconda3\envs\myenv\lib\site-packages\jupyter_cache\executors\utils.py", line 58, in single_nb_execution
    executenb(
  File "C:\Users\karen\anaconda3\envs\myenv\lib\site-packages\nbclient\client.py", line 1265, in execute
    return NotebookClient(nb=nb, resources=resources, km=km, **kwargs).execute()
  File "C:\Users\karen\anaconda3\envs\myenv\lib\site-packages\jupyter_core\utils\__init__.py", line 166, in wrapped
    return loop.run_until_complete(inner)
  File "C:\Users\karen\anaconda3\envs\myenv\lib\asyncio\base_events.py", line 649, in run_until_complete
    return future.result()
  File "C:\Users\karen\anaconda3\envs\myenv\lib\site-packages\nbclient\client.py", line 703, in async_execute
    await self.async_execute_cell(
  File "C:\Users\karen\anaconda3\envs\myenv\lib\site-packages\nbclient\client.py", line 1021, in async_execute_cell
    await self._check_raise_for_error(cell, cell_index, exec_reply)
  File "C:\Users\karen\anaconda3\envs\myenv\lib\site-packages\nbclient\client.py", line 915, in _check_raise_for_error
    raise CellExecutionError.from_cell_and_msg(cell, exec_reply_content)
nbclient.exceptions.CellExecutionError: An error occurred while executing the following cell:
------------------
print("Hay",df['vehicle_no'].nunique(),"camiones en todo el periodo de an√°lisis")
print("Hay",df['Driver_Name'].nunique(),"conductores en todo el periodo de an√°lisis"
print("Hay",df['customerID'].nunique(),"clientes √∫nicos")
------------------

[1;36m  Cell [1;32mIn[9], line 2[1;36m[0m
[1;33m    print("Hay",df['Driver_Name'].nunique(),"conductores en todo el periodo de an√°lisis"[0m
[1;37m         ^[0m
[1;31mSyntaxError[0m[1;31m:[0m '(' was never closed

SyntaxError: '(' was never closed (2234727224.py, line 2)

